Traceback (most recent call last):
  File "C:\Users\relat\anaconda3\envs\jupyter-ai\Lib\site-packages\langchain_core\output_parsers\json.py", line 66, in parse_result
    return parse_json_markdown(text)
           ^^^^^^^^^^^^^^^^^^^^^^^^^
  File "C:\Users\relat\anaconda3\envs\jupyter-ai\Lib\site-packages\langchain_core\utils\json.py", line 147, in parse_json_markdown
    return _parse_json(json_str, parser=parser)
           ^^^^^^^^^^^^^^^^^^^^^^^^^^^^^^^^^^^^
  File "C:\Users\relat\anaconda3\envs\jupyter-ai\Lib\site-packages\langchain_core\utils\json.py", line 160, in _parse_json
    return parser(json_str)
           ^^^^^^^^^^^^^^^^
  File "C:\Users\relat\anaconda3\envs\jupyter-ai\Lib\site-packages\langchain_core\utils\json.py", line 120, in parse_partial_json
    return json.loads(s, strict=strict)
           ^^^^^^^^^^^^^^^^^^^^^^^^^^^^
  File "C:\Users\relat\anaconda3\envs\jupyter-ai\Lib\json\__init__.py", line 359, in loads
    return cls(**kw).decode(s)
           ^^^^^^^^^^^^^^^^^^^
  File "C:\Users\relat\anaconda3\envs\jupyter-ai\Lib\json\decoder.py", line 337, in decode
    obj, end = self.raw_decode(s, idx=_w(s, 0).end())
               ^^^^^^^^^^^^^^^^^^^^^^^^^^^^^^^^^^^^^^
  File "C:\Users\relat\anaconda3\envs\jupyter-ai\Lib\json\decoder.py", line 355, in raw_decode
    raise JSONDecodeError("Expecting value", s, err.value) from None
json.decoder.JSONDecodeError: Expecting value: line 1 column 1 (char 0)

The above exception was the direct cause of the following exception:

Traceback (most recent call last):
  File "C:\Users\relat\anaconda3\envs\jupyter-ai\Lib\site-packages\jupyter_ai\chat_handlers\base.py", line 125, in on_message
    await self.process_message(message)
  File "C:\Users\relat\anaconda3\envs\jupyter-ai\Lib\site-packages\jupyter_ai\chat_handlers\generate.py", line 276, in process_message
    final_path = await self._generate_notebook(prompt=message.body)
                 ^^^^^^^^^^^^^^^^^^^^^^^^^^^^^^^^^^^^^^^^^^^^^^^^^^
  File "C:\Users\relat\anaconda3\envs\jupyter-ai\Lib\site-packages\jupyter_ai\chat_handlers\generate.py", line 252, in _generate_notebook
    outline = await generate_outline(prompt, llm=self.llm, verbose=True)
              ^^^^^^^^^^^^^^^^^^^^^^^^^^^^^^^^^^^^^^^^^^^^^^^^^^^^^^^^^^
  File "C:\Users\relat\anaconda3\envs\jupyter-ai\Lib\site-packages\jupyter_ai\chat_handlers\generate.py", line 56, in generate_outline
    outline = parser.parse(outline)
              ^^^^^^^^^^^^^^^^^^^^^
  File "C:\Users\relat\anaconda3\envs\jupyter-ai\Lib\site-packages\langchain_core\output_parsers\pydantic.py", line 64, in parse
    return super().parse(text)
           ^^^^^^^^^^^^^^^^^^^
  File "C:\Users\relat\anaconda3\envs\jupyter-ai\Lib\site-packages\langchain_core\output_parsers\json.py", line 72, in parse
    return self.parse_result([Generation(text=text)])
           ^^^^^^^^^^^^^^^^^^^^^^^^^^^^^^^^^^^^^^^^^^
  File "C:\Users\relat\anaconda3\envs\jupyter-ai\Lib\site-packages\langchain_core\output_parsers\pydantic.py", line 60, in parse_result
    json_object = super().parse_result(result)
                  ^^^^^^^^^^^^^^^^^^^^^^^^^^^^
  File "C:\Users\relat\anaconda3\envs\jupyter-ai\Lib\site-packages\langchain_core\output_parsers\json.py", line 69, in parse_result
    raise OutputParserException(msg, llm_output=text) from e
langchain_core.exceptions.OutputParserException: Invalid json output: The notebook will generate a random number between 1 and 100 and then print it out. The user can specify the number of times the random number should be generated.

The outline should include the following sections:
1. Introduction
2. Setup
3. Main Loop
4. Cleanup
5. Conclusion

In the "Setup" section, you should include code to initialize the random number generator. In the "Main Loop" section, you should include code to generate the random number and print it out. The "Cleanup" section should include code to close any open files or resources.
